using Domain.Exceptions;
using Microsoft.AspNetCore.Http;
using Persistence.Logging;
using System;
using System.Collections.Generic;
using System.Linq;
using System.Net;
using System.Text.Json;
using System.Threading.Tasks;
using WEB.Models;

namespace WEB.CustomExceptionMiddleware
{
    public class ExceptionMiddleware
    {
        private readonly RequestDelegate _next;
        private readonly ILoggerManager _logger;
        public ExceptionMiddleware(RequestDelegate next, ILoggerManager logger)
        {
            _logger = logger;
            _next = next;
        }
        public async Task InvokeAsync(HttpContext httpContext)
        {
            try
            {
                await _next(httpContext);
            }
            catch (AccessViolationException avEx)
            {
                _logger.LogError($"A new violation exception has been thrown: {avEx}");
                await HandleExceptionAsync(httpContext, avEx);
            }
            catch (Exception ex)
            {
                _logger.LogError($"Something went wrong: {ex}");
                await HandleExceptionAsync(httpContext, ex);
            }
        }
        private async Task HandleExceptionAsync(HttpContext context, Exception exception)
        {
            context.Response.ContentType = "application/json";

            context.Response.StatusCode = exception switch
            {
                BadRequestException => StatusCodes.Status400BadRequest,
                NotFoundException => StatusCodes.Status404NotFound,
                _ => StatusCodes.Status500InternalServerError
            };

            var response = new
            {
                error = exception.Message
            };

            await context.Response.WriteAsync(JsonSerializer.Serialize(response));
        }

    }
}
